Workbook

Sheet README
A1: Keplar growth model (editable)
A3: Purpose: show what traffic, conversion, retention and cost structure each revenue milestone would require. Goals, not forecasts. Nothing here says revenue has been achieved.
A4: Sheets: CostPerTask (real routing + list prices -> cost per successful task) | Model (inputs, three scenarios, 60 months) | Milestones | Profit1M | Illustration | Proposals | Assumptions.
A5: Colours: blue text = input you can change. Yellow fill = unsupported assumption. Green fill = verified against a dated source. Black = formula.
A6: Verified (2026-10-03): Whop billed amounts via the Whop API ($19.99 / $44.99 / $99.99; the site shows $20 / $45 / $99), Whop fees (docs.whop.com/fees), OpenRouter 5.5% credit fee, free-model request limits, the repo's routing and list prices, Vercel Hobby = non-commercial.
A7: Definitions: MRR = billed subscription revenue per month. ARR run-rate = MRR x 12, before any expense. Cash collected includes one-time sales. Lifetime deals are one-time cash and are never part of MRR or ARR.
A8: Simplifications: a new payer in month m is billed in month m; churn applies to the previous month's base; conversion is within the month; Free users cost $0 USD but share a limited pool of free-model requests; income tax and sales tax are not modeled.
A9: Not modeled: annual plans (none exist), taxes, Whop add-on fees (orchestration, billing, tax are optional extras), seasonality, price changes.

Sheet Milestones
A1: Milestones: what each level needs (targets, not forecasts)
A2: Left: when each scenario reaches the milestone. Below: the steady-state requirement, i.e. how many customers, new payers per month and qualified visits per month it takes to HOLD that MRR given the scenario's churn and conversion. Every conversion rate is an unsupported assumption until experiments E1-E5 report.
A4: Scenario / milestone | B4: Month reached | C4: MRR then | D4: Paying customers | E4: Qualified visits / mo | F4: New payers / mo | G4: Visit to paid
A5: Conservative
A6: =Model!A67 -> $1,000 MRR | B6: =Model!B67 -> not in 60 mo | C6: =Model!C67 -> - | D6: =Model!D67 -> - | E6: =Model!E67 -> - | F6: =Model!F67 -> - | G6: =Model!G67 -> -
A7: =Model!A68 -> $10,000 MRR | B7: =Model!B68 -> not in 60 mo | C7: =Model!C68 -> - | D7: =Model!D68 -> - | E7: =Model!E68 -> - | F7: =Model!F68 -> - | G7: =Model!G68 -> -
A8: =Model!A69 -> $100,000 MRR | B8: =Model!B69 -> not in 60 mo | C8: =Model!C69 -> - | D8: =Model!D69 -> - | E8: =Model!E69 -> - | F8: =Model!F69 -> - | G8: =Model!G69 -> -
A9: =Model!A70 -> $1M ARR run-rate ($83,333 MRR) | B9: =Model!B70 -> not in 60 mo | C9: =Model!C70 -> - | D9: =Model!D70 -> - | E9: =Model!E70 -> - | F9: =Model!F70 -> - | G9: =Model!G70 -> -
A10: =Model!A71 -> $5M ARR run-rate ($416,667 MRR) | B10: =Model!B71 -> not in 60 mo | C10: =Model!C71 -> - | D10: =Model!D71 -> - | E10: =Model!E71 -> - | F10: =Model!F71 -> - | G10: =Model!G71 -> -
A12: Base
A13: =Model!A132 -> $1,000 MRR | B13: =Model!B132 -> 21 | C13: =Model!C132 -> 1105.5848 | D13: =Model!D132 -> 27.982264 | E13: =Model!E132 -> 10091.25 | F13: =Model!F132 -> 4.5410625 | G13: =Model!G132 -> 0.00045
A14: =Model!A133 -> $10,000 MRR | B14: =Model!B133 -> 44 | C14: =Model!C133 -> 10264.743 | D14: =Model!D133 -> 257.97741 | E14: =Model!E133 -> 90360.104 | F14: =Model!F133 -> 40.662047 | G14: =Model!G133 -> 0.00045
A15: =Model!A134 -> $100,000 MRR | B15: =Model!B134 -> not in 60 mo | C15: =Model!C134 -> - | D15: =Model!D134 -> - | E15: =Model!E134 -> - | F15: =Model!F134 -> - | G15: =Model!G134 -> -
A16: =Model!A135 -> $1M ARR run-rate ($83,333 MRR) | B16: =Model!B135 -> not in 60 mo | C16: =Model!C135 -> - | D16: =Model!D135 -> - | E16: =Model!E135 -> - | F16: =Model!F135 -> - | G16: =Model!G135 -> -
A17: =Model!A136 -> $5M ARR run-rate ($416,667 MRR) | B17: =Model!B136 -> not in 60 mo | C17: =Model!C136 -> - | D17: =Model!D136 -> - | E17: =Model!E136 -> - | F17: =Model!F136 -> - | G17: =Model!G136 -> -
A19: Ambitious
A20: =Model!A197 -> $1,000 MRR | B20: =Model!B197 -> 4 | C20: =Model!C197 -> 1251.9482 | D20: =Model!D197 -> 28.099273 | E20: =Model!E197 -> 5926.176 | F20: =Model!F197 -> 9.126311 | G20: =Model!G197 -> 0.00154
A21: =Model!A198 -> $10,000 MRR | B21: =Model!B198 -> 16 | C21: =Model!C198 -> 11080.54 | D21: =Model!D198 -> 243.07668 | E21: =Model!E198 -> 28551.752 | F21: =Model!F198 -> 43.969698 | G21: =Model!G198 -> 0.00154
A22: =Model!A199 -> $100,000 MRR | B22: =Model!B199 -> 33 | C22: =Model!C199 -> 108693.21 | D22: =Model!D199 -> 2368.6613 | E22: =Model!E199 -> 264859.3 | F22: =Model!F199 -> 407.88333 | G22: =Model!G199 -> 0.00154
A23: =Model!A200 -> $1M ARR run-rate ($83,333 MRR) | B23: =Model!B200 -> 31 | C23: =Model!C200 -> 83535.885 | D23: =Model!D200 -> 1820.8385 | E23: =Model!E200 -> 203800.63 | F23: =Model!F200 -> 313.85298 | G23: =Model!G200 -> 0.00154
A24: =Model!A201 -> $5M ARR run-rate ($416,667 MRR) | B24: =Model!B201 -> 57 | C24: =Model!C201 -> 423842.3 | D24: =Model!D201 -> 8831.0636 | E24: =Model!E201 -> 400000 | F24: =Model!F201 -> 616 | G24: =Model!G201 -> 0.00154
A26: Steady-state requirement (holds the MRR level, per scenario)
A27: Target | B27: Scenario | C27: MRR target | D27: Blended billed ARPU | E27: Customers needed | F27: Blended monthly churn (by customers) | G27: New payers / month to hold | H27: Visit to paid | I27: Qualified visits / month to hold | J27: Of which: visits needed for growth (+10%/mo)
A28: $1,000 MRR | B28: Conservative | C28: 1000 | D28: =(Model!$C$28*Model!$C$6+Model!$C$29*Model!$C$7+Model!$C$30*Model!$C$8)*(1+Model!$C$38) -> 32.59 | E28: =C28/D28 -> 30.684259 | F28: =Model!$C$28*Model!$C$35+Model!$C$29*Model!$C$36+Model!$C$30*Model!$C$37 -> 0.1046 | G28: =E28*F28 -> 3.2095735 | H28: =Model!$C$25*Model!$C$26*Model!$C$27 -> 0.00013125 | I28: =G28/H28 -> 24453.893 | J28: =(G28+E28*0.1/(1+0.1))/H28 -> 45707.06
A29: $1,000 MRR | B29: Base | C29: 1000 | D29: =(Model!$D$28*Model!$D$6+Model!$D$29*Model!$D$7+Model!$D$30*Model!$D$8)*(1+Model!$D$38) -> 37.4748 | E29: =C29/D29 -> 26.684599 | F29: =Model!$D$28*Model!$D$35+Model!$D$29*Model!$D$36+Model!$D$30*Model!$D$37 -> 0.075 | G29: =E29*F29 -> 2.0013449 | H29: =Model!$D$25*Model!$D$26*Model!$D$27 -> 0.00045 | I29: =G29/H29 -> 4447.4331 | J29: =(G29+E29*0.1/(1+0.1))/H29 -> 9838.2611
A30: $1,000 MRR | B30: Ambitious | C30: 1000 | D30: =(Model!$E$28*Model!$E$6+Model!$E$29*Model!$E$7+Model!$E$30*Model!$E$8)*(1+Model!$E$38) -> 44.0895 | E30: =C30/D30 -> 22.681137 | F30: =Model!$E$28*Model!$E$35+Model!$E$29*Model!$E$36+Model!$E$30*Model!$E$37 -> 0.05675 | G30: =E30*F30 -> 1.2871545 | H30: =Model!$E$25*Model!$E$26*Model!$E$27 -> 0.00154 | I30: =G30/H30 -> 835.81464 | J30: =(G30+E30*0.1/(1+0.1))/H30 -> 2174.7247
A31: $10,000 MRR | B31: Conservative | C31: 10000 | D31: =(Model!$C$28*Model!$C$6+Model!$C$29*Model!$C$7+Model!$C$30*Model!$C$8)*(1+Model!$C$38) -> 32.59 | E31: =C31/D31 -> 306.84259 | F31: =Model!$C$28*Model!$C$35+Model!$C$29*Model!$C$36+Model!$C$30*Model!$C$37 -> 0.1046 | G31: =E31*F31 -> 32.095735 | H31: =Model!$C$25*Model!$C$26*Model!$C$27 -> 0.00013125 | I31: =G31/H31 -> 244538.93 | J31: =(G31+E31*0.1/(1+0.1))/H31 -> 457070.6
A32: $10,000 MRR | B32: Base | C32: 10000 | D32: =(Model!$D$28*Model!$D$6+Model!$D$29*Model!$D$7+Model!$D$30*Model!$D$8)*(1+Model!$D$38) -> 37.4748 | E32: =C32/D32 -> 266.84599 | F32: =Model!$D$28*Model!$D$35+Model!$D$29*Model!$D$36+Model!$D$30*Model!$D$37 -> 0.075 | G32: =E32*F32 -> 20.013449 | H32: =Model!$D$25*Model!$D$26*Model!$D$27 -> 0.00045 | I32: =G32/H32 -> 44474.331 | J32: =(G32+E32*0.1/(1+0.1))/H32 -> 98382.611
A33: $10,000 MRR | B33: Ambitious | C33: 10000 | D33: =(Model!$E$28*Model!$E$6+Model!$E$29*Model!$E$7+Model!$E$30*Model!$E$8)*(1+Model!$E$38) -> 44.0895 | E33: =C33/D33 -> 226.81137 | F33: =Model!$E$28*Model!$E$35+Model!$E$29*Model!$E$36+Model!$E$30*Model!$E$37 -> 0.05675 | G33: =E33*F33 -> 12.871545 | H33: =Model!$E$25*Model!$E$26*Model!$E$27 -> 0.00154 | I33: =G33/H33 -> 8358.1464 | J33: =(G33+E33*0.1/(1+0.1))/H33 -> 21747.247
A34: $100,000 MRR | B34: Conservative | C34: 100000 | D34: =(Model!$C$28*Model!$C$6+Model!$C$29*Model!$C$7+Model!$C$30*Model!$C$8)*(1+Model!$C$38) -> 32.59 | E34: =C34/D34 -> 3068.4259 | F34: =Model!$C$28*Model!$C$35+Model!$C$29*Model!$C$36+Model!$C$30*Model!$C$37 -> 0.1046 | G34: =E34*F34 -> 320.95735 | H34: =Model!$C$25*Model!$C$26*Model!$C$27 -> 0.00013125 | I34: =G34/H34 -> 2445389.3 | J34: =(G34+E34*0.1/(1+0.1))/H34 -> 4570706
A35: $100,000 MRR | B35: Base | C35: 100000 | D35: =(Model!$D$28*Model!$D$6+Model!$D$29*Model!$D$7+Model!$D$30*Model!$D$8)*(1+Model!$D$38) -> 37.4748 | E35: =C35/D35 -> 2668.4599 | F35: =Model!$D$28*Model!$D$35+Model!$D$29*Model!$D$36+Model!$D$30*Model!$D$37 -> 0.075 | G35: =E35*F35 -> 200.13449 | H35: =Model!$D$25*Model!$D$26*Model!$D$27 -> 0.00045 | I35: =G35/H35 -> 444743.31 | J35: =(G35+E35*0.1/(1+0.1))/H35 -> 983826.11
A36: $100,000 MRR | B36: Ambitious | C36: 100000 | D36: =(Model!$E$28*Model!$E$6+Model!$E$29*Model!$E$7+Model!$E$30*Model!$E$8)*(1+Model!$E$38) -> 44.0895 | E36: =C36/D36 -> 2268.1137 | F36: =Model!$E$28*Model!$E$35+Model!$E$29*Model!$E$36+Model!$E$30*Model!$E$37 -> 0.05675 | G36: =E36*F36 -> 128.71545 | H36: =Model!$E$25*Model!$E$26*Model!$E$27 -> 0.00154 | I36: =G36/H36 -> 83581.464 | J36: =(G36+E36*0.1/(1+0.1))/H36 -> 217472.47
A37: $1M ARR | B37: Conservative | C37: 83333.333 | D37: =(Model!$C$28*Model!$C$6+Model!$C$29*Model!$C$7+Model!$C$30*Model!$C$8)*(1+Model!$C$38) -> 32.59 | E37: =C37/D37 -> 2557.0216 | F37: =Model!$C$28*Model!$C$35+Model!$C$29*Model!$C$36+Model!$C$30*Model!$C$37 -> 0.1046 | G37: =E37*F37 -> 267.46446 | H37: =Model!$C$25*Model!$C$26*Model!$C$27 -> 0.00013125 | I37: =G37/H37 -> 2037824.4 | J37: =(G37+E37*0.1/(1+0.1))/H37 -> 3808921.6
A38: $1M ARR | B38: Base | C38: 83333.333 | D38: =(Model!$D$28*Model!$D$6+Model!$D$29*Model!$D$7+Model!$D$30*Model!$D$8)*(1+Model!$D$38) -> 37.4748 | E38: =C38/D38 -> 2223.7166 | F38: =Model!$D$28*Model!$D$35+Model!$D$29*Model!$D$36+Model!$D$30*Model!$D$37 -> 0.075 | G38: =E38*F38 -> 166.77874 | H38: =Model!$D$25*Model!$D$26*Model!$D$27 -> 0.00045 | I38: =G38/H38 -> 370619.43 | J38: =(G38+E38*0.1/(1+0.1))/H38 -> 819855.1
A39: $1M ARR | B39: Ambitious | C39: 83333.333 | D39: =(Model!$E$28*Model!$E$6+Model!$E$29*Model!$E$7+Model!$E$30*Model!$E$8)*(1+Model!$E$38) -> 44.0895 | E39: =C39/D39 -> 1890.0948 | F39: =Model!$E$28*Model!$E$35+Model!$E$29*Model!$E$36+Model!$E$30*Model!$E$37 -> 0.05675 | G39: =E39*F39 -> 107.26288 | H39: =Model!$E$25*Model!$E$26*Model!$E$27 -> 0.00154 | I39: =G39/H39 -> 69651.22 | J39: =(G39+E39*0.1/(1+0.1))/H39 -> 181227.06
A40: $5M ARR | B40: Conservative | C40: 416666.67 | D40: =(Model!$C$28*Model!$C$6+Model!$C$29*Model!$C$7+Model!$C$30*Model!$C$8)*(1+Model!$C$38) -> 32.59 | E40: =C40/D40 -> 12785.108 | F40: =Model!$C$28*Model!$C$35+Model!$C$29*Model!$C$36+Model!$C$30*Model!$C$37 -> 0.1046 | G40: =E40*F40 -> 1337.3223 | H40: =Model!$C$25*Model!$C$26*Model!$C$27 -> 0.00013125 | I40: =G40/H40 -> 10189122 | J40: =(G40+E40*0.1/(1+0.1))/H40 -> 19044608
A41: $5M ARR | B41: Base | C41: 416666.67 | D41: =(Model!$D$28*Model!$D$6+Model!$D$29*Model!$D$7+Model!$D$30*Model!$D$8)*(1+Model!$D$38) -> 37.4748 | E41: =C41/D41 -> 11118.583 | F41: =Model!$D$28*Model!$D$35+Model!$D$29*Model!$D$36+Model!$D$30*Model!$D$37 -> 0.075 | G41: =E41*F41 -> 833.89371 | H41: =Model!$D$25*Model!$D$26*Model!$D$27 -> 0.00045 | I41: =G41/H41 -> 1853097.1 | J41: =(G41+E41*0.1/(1+0.1))/H41 -> 4099275.5
A42: $5M ARR | B42: Ambitious | C42: 416666.67 | D42: =(Model!$E$28*Model!$E$6+Model!$E$29*Model!$E$7+Model!$E$30*Model!$E$8)*(1+Model!$E$38) -> 44.0895 | E42: =C42/D42 -> 9450.4738 | F42: =Model!$E$28*Model!$E$35+Model!$E$29*Model!$E$36+Model!$E$30*Model!$E$37 -> 0.05675 | G42: =E42*F42 -> 536.31439 | H42: =Model!$E$25*Model!$E$26*Model!$E$27 -> 0.00154 | I42: =G42/H42 -> 348256.1 | J42: =(G42+E42*0.1/(1+0.1))/H42 -> 906135.31
A44: Reading it: 'to hold' is the traffic that replaces churned customers; growing needs more. Column J adds the extra new payers needed to keep growing 10% a month at that size. Compare these visit counts with what two founders and a $0 budget can plausibly earn; no audience size is claimed.
A46: Annual summary by scenario (sums of the monthly columns)
...

Sheet Model
A1: Keplar revenue and cost model: 60 monthly periods, three scenarios (targets and what-ifs, NOT forecasts)
A2: Blue = input you can edit. Yellow = unsupported assumption (no Keplar data yet). Green = verified against a source on 2026-10-03. Black = formula. Currency USD. MRR/ARR here are billed subscription revenue; lifetime deals never count as recurring.
A4: Input | B4: Unit | C4: Conservative | D4: Base | E4: Ambitious | F4: Evidence | G4: Source / experiment that would validate it
A5: Prices and payment costs (Whop)
A6: Lite: amount Whop bills per month (site shows $20) | B6: $ | C6: 19.99 | D6: =C6 -> 19.99 | E6: =C6 -> 19.99 | F6: VERIFIED | G6: Whop API plan_qpgb6JV0jhQGj renewal price, read 2026-10-03
A7: Plus: billed per month | B7: $ | C7: 44.99 | D7: =C7 -> 44.99 | E7: =C7 -> 44.99 | F7: VERIFIED | G7: Whop API plan_wd9Xs4iDlwvDi
A8: Pro: billed per month (site shows $99) | B8: $ | C8: 99.99 | D8: =C8 -> 99.99 | E8: =C8 -> 99.99 | F8: VERIFIED | G8: Whop API plan_M6ztgSJDucMJA renewal $99.99
A9: Whop card fee, percent of each payment | B9: % | C9: 0.027 | D9: =C9 -> 0.027 | E9: =C9 -> 0.027 | F9: VERIFIED | G9: docs.whop.com/fees, 2026-10-03: 2.7% + $0.30 domestic card
A10: Whop card fee, fixed per payment | B10: $ | C10: 0.3 | D10: =C10 -> 0.3 | E10: =C10 -> 0.3 | F10: VERIFIED | G10: docs.whop.com/fees
A11: Share of payments that are international cards | B11: % | C11: 0.3 | D11: =C11 -> 0.3 | E11: =C11 -> 0.3 | F11: ASSUMPTION | G11: No payment data yet. E8: read the real mix from Whop after the first 20 payments
A12: Extra fee on international cards + FX (1.5% + 1.0%) | B12: % | C12: 0.025 | D12: =C12 -> 0.025 | E12: =C12 -> 0.025 | F12: VERIFIED | G12: docs.whop.com/fees (international +1.5%, currency conversion +1%)
A13: Dispute fee per chargeback | B13: $ | C13: 15 | D13: =C13 -> 15 | E13: =C13 -> 15 | F13: VERIFIED | G13: docs.whop.com/fees
A14: Share of payments disputed | B14: % | C14: 0.004 | D14: 0.002 | E14: 0.001 | F14: ASSUMPTION | G14: Track from Whop: disputes / payments
A15: Refunds, share of billed revenue (fees are not returned) | B15: % | C15: 0.05 | D15: 0.03 | E15: 0.02 | F15: ASSUMPTION | G15: Track refunds in /admin/growth; E8
A16: Share of new paying customers who get an introductory discount | B16: % | C16: 0.15 | D16: 0.1 | E16: 0.05 | F16: ASSUMPTION | G16: Only if a promo is approved (OFFER.md); none is live
A17: Discount depth on that first payment | B17: % | C17: 0.2 | D17: =C17 -> 0.2 | E17: =C17 -> 0.2 | F17: ASSUMPTION | G17: OFFER.md proposal; not live
A18: OpenRouter fee on credit purchases (provider spend) | B18: % | C18: 0.055 | D18: =C18 -> 0.055 | E18: =C18 -> 0.055 | F18: VERIFIED | G18: OpenRouter FAQ/pricing: 5.5% fee on credit purchases, 2026-10-03
A19: Acquisition and conversion funnel (no Keplar data yet: everything here is an ASSUMPTION)
A20: Qualified visits in month 1 (organic + community, $0 spend) | B20: visits/mo | C20: 500 | D20: 1500 | E20: 4000 | F20: ASSUMPTION | G20: Qualified = reached a public page and stayed. E1/E2: measure from /admin/growth after the first 4 weeks
A21: Monthly growth of qualified visits | B21: %/mo | C21: 0.06 | D21: 0.1 | E21: 0.14 | F21: ASSUMPTION | G21: Needs search + demo content to compound; E1, E2
A22: Ceiling on organic visits (founder time / channel size) | B22: visits/mo | C22: 40000 | D22: 120000 | E22: 400000 | F22: ASSUMPTION | G22: Unknown audience sizes; no figure is claimed
A23: Paid acquisition spend per month (PROPOSAL only; $0 budget today) | B23: $/mo | C23: 0 | D23: =C23 -> 0 | E23: =C23 -> 0 | F23: VERIFIED | G23: Budget is $0. Change only after a budget, loss limit and authorization exist
A24: Cost per qualified visit if paid is ever used | B24: $ | C24: 1.5 | D24: =C24 -> 1.5 | E24: =C24 -> 1.5 | F24: ASSUMPTION | G24: Not tested; E11 would measure it with a capped test
A25: Visit to account created | B25: % | C25: 0.015 | D25: 0.025 | E25: 0.04 | F25: ASSUMPTION | G25: Anonymous use is allowed, so some visitors never sign up. Measure: seo_events landing_view vs signup_complete
A26: Account to activated (answer, then a deliberate action) | B26: % | C26: 0.35 | D26: 0.45 | E26: 0.55 | F26: ASSUMPTION | G26: Definition in docs/growth/ACTIVATION.md. Measure: growth_events
A27: Activated user to paying within the month | B27: % | C27: 0.025 | D27: 0.04 | E27: 0.07 | F27: ASSUMPTION | G27: Price is >2x single-model subscriptions at Plus. E4/E5 test the offer
A28: New payers choosing Lite | B28: % | C28: 0.65 | D28: 0.55 | E28: 0.45 | F28: ASSUMPTION | G28: Measure plan mix at the first 10 payers
A29: New payers choosing Plus | B29: % | C29: 0.28 | D29: 0.35 | E29: 0.4 | F29: ASSUMPTION
A30: New payers choosing Pro (remainder) | B30: % | C30: =1-C28-C29 -> 0.07 | D30: =1-D28-D29 -> 0.1 | E30: =1-E28-E29 -> 0.15 | F30: FORMULA | G30: Formula: 1 minus Lite minus Plus
A31: Referral: invites sent per paying customer per month (OFF) | B31: per mo | C31: 0 | D31: =C31 -> 0 | E31: =C31 -> 0 | F31: VERIFIED | G31: No reward or invite program is live. Costed proposal in SHARING.md
A32: Referral: invited person creates an account | B32: % | C32: 0.1 | D32: =C32 -> 0.1 | E32: =C32 -> 0.1 | F32: ASSUMPTION | G32: Only relevant if the proposal is approved
A33: Referral: reward cost per converted invitee | B33: $ | C33: 0 | D33: =C33 -> 0 | E33: =C33 -> 0 | F33: VERIFIED | G33: No reward is offered today
A34: Retention (all ASSUMPTIONS: no cohort exists yet)
A35: Monthly churn, Lite | B35: %/mo | C35: 0.12 | D35: 0.09 | E35: 0.07 | F35: ASSUMPTION | G35: Fix churn causes before expanding acquisition (RETENTION.md). Measure by cohort
A36: Monthly churn, Plus | B36: %/mo | C36: 0.08 | D36: 0.06 | E36: 0.05 | F36: ASSUMPTION
A37: Monthly churn, Pro | B37: %/mo | C37: 0.06 | D37: 0.045 | E37: 0.035 | F37: ASSUMPTION
A38: Expansion: add-ons, top-ups and upgrades as a share of subscription MRR | B38: % | C38: 0 | D38: 0.02 | E38: 0.05 | F38: ASSUMPTION | G38: No top-up product exists yet. Treat 0% as the only verified value
A39: Usage and cost to serve
A40: Provider cost per successful paid task (blended, from CostPerTask) | B40: $ | C40: =CostPerTask!$B$76 -> 0.0084608401 | D40: =CostPerTask!$B$76 -> 0.0084608401 | E40: =CostPerTask!$B$76 -> 0.0084608401 | F40: REPO | G40: CostPerTask sheet: real routing + list prices; tokens are assumptions
A41: Successful tasks per month, Lite customer | B41: tasks | C41: 250 | D41: 150 | E41: 120 | F41: ASSUMPTION | G41: Allowance supports ~400 moderate tasks. Measure from compute_ledger
...

Sheet CostPerTask
A1: Model cost per successful task (from the repo's real routing and list prices)
A2: Sources: src/lib/orchestration/{router,live-catalog,live-synthesizer,extractor,verifier}.ts, docs/cost-model.md. Prices are OpenRouter/provider list prices dated 2026-09-28 in the repo. Token counts are ASSUMPTIONS (yellow) taken from the classifier/router estimates for a ~640-token prompt; replace them with the ledger's real averages once paid traffic exists.
A4: A. Price table ($ per 1M tokens)
A5: Model | B5: Input $/1M | C5: Output $/1M | I5: Role in the pipeline
A6: deepseek-v4-flash | B6: 0.05 | C6: 0.1 | I6: panel (cheapest)
A7: gpt-6-luna | B7: 0.1 | C7: 0.5 | I7: panel + response extractor
A8: nemotron-3-super | B8: 0.08 | C8: 0.45 | I8: panel
A9: qwen3.8-flash | B9: 0.15 | C9: 0.47 | I9: panel (complex only)
A10: glm-5.3-flash | B10: 0.15 | C10: 0.5 | I10: panel (complex only)
A11: gpt-oss-20b | B11: 0.02 | C11: 0.09 | I11: simple answers + verifier
A12: gemini-3.8-flash | B12: 0.75 | C12: 3.75 | I12: synthesizer / judge
A14: B. Token and behaviour assumptions (yellow = unsupported until the compute ledger has real averages)
A15: Prompt input tokens per call (question + 600-token system/context) | B15: 640
A16: Panel answer tokens, moderate (router estimate 900) | B16: 900
A17: Panel answer tokens, complex (router estimate 1,600) | B17: 1600
A18: Simple single-model answer tokens | B18: 350
A19: Billed-output multiplier for reasoning tokens (low effort) | B19: 1.25
A20: Extractor output tokens | B20: 700
A21: Verifier output tokens | B21: 600
A22: Synthesizer extra input tokens (extraction + verification notes) | B22: 1500
A23: Synthesizer output tokens (final answer) | B23: 900
A24: Share of complex questions where the judge also runs | B24: 0.6
A25: Retry / partial-failure overhead on cost | B25: 0.06
A26: Share of runs that fail after spending | B26: 0.03
... A33: Meter margin multiplier (limits.ts METER_MARGIN) | B33: 1.1
A35: C1. Simple question (one model, nothing to compare)
A36: Call | B36: Model | C36: Tokens in | D36: Tokens out | E36: Cost $
A37: Panel answer | B37: gpt-oss-20b | C37: =$B$15 -> 640 | D37: =$B$18 -> 350 | E37: =(C37*$B$11+D37*$B$19*$C$11)/1000000 -> 5.2175e-05
A38: Total provider cost, one run | E38: =SUM(E37) -> 5.2175e-05
A40: C2. Light-moderate question (2-model panel)
A41: Call | B41: Model | C41: Tokens in | D41: Tokens out | E41: Cost $
A42: Panel answer | B42: deepseek-v4-flash | C42: =$B$15 -> 640 | D42: =$B$16 -> 900 | E42: =(C42*$B$6+D42*$B$19*$C$6)/1000000 -> 0.0001445
A43: Panel answer | B43: gpt-6-luna | C43: =$B$15 -> 640 | D43: =$B$16 -> 900 | E43: =(C43*$B$7+D43*$B$19*$C$7)/1000000 -> 0.0006265
A44: Response extractor (stances + claims) | B44: gpt-6-luna | C44: =($B$15+2*$B$16) -> 2440 | D44: =$B$20 -> 700 | E44: =(C44*$B$7+D44*$B$19*$C$7)/1000000 -> 0.0006815
A45: Verifier (cheap reviewer) | B45: gpt-oss-20b | C45: =($B$15+2*$B$16) -> 2440 | D45: =$B$21 -> 600 | E45: =(C45*$B$11+D45*$B$19*$C$11)/1000000 -> 0.0001163
A46: Synthesizer (writes the one answer) | B46: gemini-3.8-flash | C46: =($B$15+$B$22) -> 2140 | D46: =$B$23 -> 900 | E46: =(C46*$B$12+D46*$B$19*$C$12)/1000000 -> 0.00582375
A47: Total provider cost, one run | E47: =SUM(E42:E46) -> 0.00739255
A49: C3. Moderate question (3-model panel)
A50: Call | B50: Model | C50: Tokens in | D50: Tokens out | E50: Cost $
A51: Panel answer | B51: deepseek-v4-flash | C51: =$B$15 -> 640 | D51: =$B$16 -> 900 | E51: =(C51*$B$6+D51*$B$19*$C$6)/1000000 -> 0.0001445
...

Sheet Profit1M
A1: What it takes to earn $1,000,000 a year in operating profit (a structure, not a forecast)
A2: Steady state: contribution per paying customer per month, minus fixed costs and pay, must add up to the target. Two cases per scenario: (A) before any pay to the founders, (B) after paying the team the amounts in the yellow cells. Change any blue cell.
A4: Target annual operating profit | B4: 1000000
A5: Team cost per year in case B (2 founders + 1 support/contract hire; ASSUMPTION) | B5: 330000
A6: Marketing per month in case B (paid acquisition is a proposal; ASSUMPTION) | B6: 5000
A8: Per paying customer, per month | B8: Conservative | C8: Base | D8: Ambitious
A9: Blended billed revenue (mix x price x (1+expansion)) | B9: =(Model!$C$28*Model!$C$6+Model!$C$29*Model!$C$7+Model!$C$30*Model!$C$8)*(1+Model!$C$38) -> 32.59 | C9: =(Model!$D$28*Model!$D$6+Model!$D$29*Model!$D$7+Model!$D$30*Model!$D$8)*(1+Model!$D$38) -> 37.4748 | D9: =(Model!$E$28*Model!$E$6+Model!$E$29*Model!$E$7+Model!$E$30*Model!$E$8)*(1+Model!$E$38) -> 44.0895
A10: less refunds | B10: =-B9*Model!$C$15 -> -1.6295 | C10: =-C9*Model!$D$15 -> -1.124244 | D10: =-D9*Model!$E$15 -> -0.88179
A11: less payment fees and disputes | B11: =-(B9*(Model!$C$9+Model!$C$11*Model!$C$12)+Model!$C$10+Model!$C$14*Model!$C$13) -> -1.484355 | C11: =-(C9*(Model!$D$9+Model!$D$11*Model!$D$12)+Model!$D$10+Model!$D$14*Model!$D$13) -> -1.6228806 | D11: =-(D9*(Model!$E$9+Model!$E$11*Model!$E$12)+Model!$E$10+Model!$E$14*Model!$E$13) -> -1.8360877
A12: less provider cost: answers | B12: =-(Model!$C$28*Model!$C$41+Model!$C$29*Model!$C$42+Model!$C$30*Model!$C$43)*Model!$C$40 -> -3.4477924 | C12: =-(Model!$D$28*Model!$D$41+Model!$D$29*Model!$D$42+Model!$D$30*Model!$D$43)*Model!$D$40 -> -2.326731 | D12: =-(Model!$E$28*Model!$E$41+Model!$E$29*Model!$E$42+Model!$E$30*Model!$E$43)*Model!$E$40 -> -2.2336618
A13: less provider cost: images / Deep Research | B13: =-(Model!$C$28*Model!$C$44+Model!$C$29*Model!$C$45+Model!$C$30*Model!$C$46) -> -1.19 | C13: =-(Model!$D$28*Model!$D$44+Model!$D$29*Model!$D$45+Model!$D$30*Model!$D$46) -> -0.925 | D13: =-(Model!$E$28*Model!$E$44+Model!$E$29*Model!$E$45+Model!$E$30*Model!$E$46) -> -0.85
A14: less OpenRouter 5.5% fee | B14: =(B12+B13)*Model!$C$18 -> -0.25507858 | C14: =(C12+C13)*Model!$D$18 -> -0.17884521 | D14: =(D12+D13)*Model!$E$18 -> -0.1696014
A15: less support (time valued) | B15: =-Model!$C$55/60*Model!$C$56 -> -3 | C15: =-Model!$D$55/60*Model!$D$56 -> -2 | D15: =-Model!$E$55/60*Model!$E$56 -> -1.5
A16: less variable infrastructure (paying customer only) | B16: =-Model!$C$54 -> -0.04 | C16: =-Model!$D$54 -> -0.03 | D16: =-Model!$E$54 -> -0.02
A17: Contribution per paying customer per month (sum of the lines above) | B17: =SUM(B9:B16) -> 21.543274 | C17: =SUM(C9:C16) -> 29.267099 | D17: =SUM(D9:D16) -> 36.598359
A19: Required structure | B19: Conservative | C19: Base | D19: Ambitious
A20: A. Fixed costs per year before founder pay | B20: =(Model!$C$53+Model!$C$57)*12 -> 1200 | C20: =(Model!$D$53+Model!$D$57)*12 -> 1200 | D20: =(Model!$E$53+Model!$E$57)*12 -> 1200
A21: A. Paying customers needed | B21: =($B$4+B20)/(B17*12) -> 3872.8251 | C21: =($B$4+C20)/(C17*12) -> 2850.7551 | D21: =($B$4+D20)/(D17*12) -> 2279.7015
A22: A. MRR needed | B22: =B21*B9 -> 126215.37 | C22: =C21*C9 -> 106831.48 | D22: =D21*D9 -> 100510.9
A23: A. ARR run-rate needed | B23: =B22*12 -> 1514584.5 | C23: =C22*12 -> 1281977.7 | D23: =D22*12 -> 1206130.8
A24: A. New payers per month just to replace churn | B24: =B21*B32 -> 405.09751 | C24: =C21*C32 -> 213.80664 | D24: =D21*D32 -> 129.37306
A25: A. Qualified visits per month to replace churn (visit-to-paid from scenario) | B25: =B24/B33 -> 3086457.2 | C25: =C24/C33 -> 475125.86 | D25: =D24/D33 -> 84008.48
A26: B. Fixed + team + marketing per year | B26: =B20+$B$5+$B$6*12 -> 391200 | C26: =C20+$B$5+$B$6*12 -> 391200 | D26: =D20+$B$5+$B$6*12 -> 391200
A27: B. Paying customers needed | B27: =($B$4+B26)/(B17*12) -> 5381.4166 | C27: =($B$4+C26)/(C17*12) -> 3961.2171 | D27: =($B$4+D26)/(D17*12) -> 3167.7194
A28: B. MRR needed | B28: =B27*B9 -> 175380.37 | C28: =C27*C9 -> 148445.82 | D28: =D27*D9 -> 139663.17
A29: B. ARR run-rate needed | B29: =B28*12 -> 2104564.4 | C29: =C28*12 -> 1781349.8 | D29: =D28*12 -> 1675958
A30: B. New payers per month to replace churn | B30: =B27*B32 -> 562.89618 | C30: =C27*C32 -> 297.09128 | D30: =D27*D32 -> 179.76808
A31: B. Qualified visits per month to replace churn | B31: =B30/B33 -> 4288732.8 | C31: =C30/C33 -> 660202.85 | D31: =D30/D33 -> 116732.52
A32: Blended monthly churn | B32: =Model!$C$28*Model!$C$35+Model!$C$29*Model!$C$36+Model!$C$30*Model!$C$37 -> 0.1046 | C32: =Model!$D$28*Model!$D$35+Model!$D$29*Model!$D$36+Model!$D$30*Model!$D$37 -> 0.075 | D32: =Model!$E$28*Model!$E$35+Model!$E$29*Model!$E$36+Model!$E$30*Model!$E$37 -> 0.05675
A33: Visit to paid conversion | B33: =Model!$C$25*Model!$C$26*Model!$C$27 -> 0.00013125 | C33: =Model!$D$25*Model!$D$26*Model!$D$27 -> 0.00045 | D33: =Model!$E$25*Model!$E$26*Model!$E$27 -> 0.00154
A34: Contribution margin on billed revenue | B34: =B17/B9 -> 0.6610394 | C34: =C17/C9 -> 0.7809808 | D34: =D17/D9 -> 0.8300924
A36: Notes: (1) Operating profit here is a steady-state cash view, before income tax. (2) It ignores the ramp: reaching these customer counts takes time and a growing audience (see Milestones). (3) Marketing in case B is a placeholder for a budget that does not exist; paid acquisition is a proposal. (4) Heavy users, price changes, refunds above plan and free-model capacity are not stress-tested here: change the blue inputs on Model.

Sheet Illustration
A1: The 2,000 / 10,000 customer illustration: run rate, not earnings
A2: Customers x price, annualized, is a revenue RUN RATE before any expense. It is a goal to be tested, not a forecast, and not profit. The lower half subtracts the Base-scenario cost to serve one Plus customer.
B4: 2,000 customers | C4: 10,000 customers
A5: Paying customers | B5: 2000 | C5: 10000
A6: Price per month used in the illustration ($45 Plus; Whop bills $44.99) | B6: 45 | C6: 45
A7: MRR | B7: =B5*B6 -> 90000 | C7: =C5*C6 -> 450000
A8: ARR run-rate (MRR x 12) BEFORE expenses | B8: =B7*12 -> 1080000 | C8: =C7*12 -> 5400000
A10: Same customers at Base-scenario unit costs, per month
A11: Refunds | B11: =-B7*Model!$D$15 -> -2700 | C11: =-C7*Model!$D$15 -> -13500
A12: Payment fees (2.7% + $0.30, international share, disputes) | B12: =-(B7*(Model!$D$9+Model!$D$11*Model!$D$12)+B5*(Model!$D$10+Model!$D$14*Model!$D$13)) -> -3765 | C12: =-(C7*(Model!$D$9+Model!$D$11*Model!$D$12)+C5*(Model!$D$10+Model!$D$14*Model!$D$13)) -> -18825
A13: Provider cost: answers (Plus usage) | B13: =-B5*Model!$D$42*Model!$D$40 -> -5922.5881 | C13: =-C5*Model!$D$42*Model!$D$40 -> -29612.94
A14: Provider cost: images / Deep Research (Plus) | B14: =-B5*Model!$D$45 -> -3000 | C14: =-C5*Model!$D$45 -> -15000
A15: OpenRouter 5.5% fee | B15: =(B13+B14)*Model!$D$18 -> -490.74235 | C15: =(C13+C14)*Model!$D$18 -> -2453.7117
A16: Support (time valued) | B16: =-B5*Model!$D$55/60*Model!$D$56 -> -4000 | C16: =-C5*Model!$D$55/60*Model!$D$56 -> -20000
A17: Infrastructure (fixed + variable) | B17: =-(Model!$D$53+Model!$D$54*B5*2) -> -180 | C17: =-(Model!$D$53+Model!$D$54*C5*2) -> -660
A18: Other fixed | B18: =-Model!$D$57 -> -40 | C18: =-Model!$D$57 -> -40
A19: Operating profit per month (before founder pay and income tax) | B19: =B7+SUM(B11:B18) -> 69901.67 | C19: =C7+SUM(C11:C18) -> 349908.35
A20: Operating profit per year | B20: =B19*12 -> 838820.03 | C20: =C19*12 -> 4198900.2
A21: Share of the run rate that is profit | B21: =B20/B8 -> 0.77668522 | C21: =C20/C8 -> 0.77757411
A23: Not modeled here: acquisition cost, price changes, churn replacement, free-model capacity limit (about 150 Free questions a day product-wide today), and Vercel/Neon cost growth at that scale.

Sheet Proposals
A1: Costed proposals (nothing here is live; no billing or price changes)
A3: 1. Referral reward (proposal): invitee and referrer each get bonus credits after the invitee's first activated answer
A4: Bonus credits per person (a credit = $0.002 of provider cost x 1.1 margin) | B4: 300
A5: Provider cost if fully used, per person | B5: =B4*0.002/1.1 -> 0.54545455
A6: Persons rewarded per qualifying referral (referrer + invitee) | B6: 2
A7: Max rewarded referrals per referrer | B7: 5
A8: Cost per qualifying referral if fully used | B8: =B5*B6 -> 1.0909091
A9: Maximum exposure per referrer | B9: =B8*B7 -> 5.4545455
A10: Assumed abuse / fake-account share (adds to cost; verification required) | B10: 0.25
A11: Exposure per referrer incl. abuse allowance | B11: =B9*(1+B10) -> 6.8181818
A12: Referrers in a first test (cap) | B12: 50
A13: MAXIMUM total exposure of a capped test | B13: =B11*B12 -> 340.90909
A14: Break-even: one Lite payer's contribution over 3 months (Base) | B14: =3*(Model!$D$6*(1-Model!$D$15)-(Model!$D$6*Model!$D$9+Model!$D$10)-Model!$D$41*Model!$D$40*(1+Model!$D$18)) -> 51.634926
A16: Eligibility: signed-in, email-verified, one reward per payer, invitee must be a new account that completes a real answer; rewards are credits (no cash) and expire in 30 days. Stop if exposure > cap or if fewer than 1 in 10 rewarded invitees activates.
A18: 2. Lifetime deal (NOT recommended now): cash is one-time; the service obligation is not
A19: Price | B19: 149
A20: Units sold in the test | B20: 100
A21: Cash collected (one-time; never recurring) | B21: =B19*B20 -> 14900
A22: Payment fees on that cash | B22: =B20*(B19*Model!$D$9+Model!$D$10) -> 432.3
A23: Monthly provider cost to serve one lifetime customer (Lite-level usage, Base) | B23: =Model!$D$41*Model!$D$40*(1+Model!$D$18) -> 1.338928
A24: Months the obligation is assumed to last | B24: 36
A25: Service obligation = units x monthly cost x months | B25: =B20*B23*B24 -> 4820.1406
A26: Cash minus fees minus obligation (before support and infra) | B26: =B21-B22-B25 -> 9647.5594
A27: Break-even months of service at this price | B27: =(B19-B19*Model!$D$9-Model!$D$10)/B23 -> 108.05436
A29: Counting rule: lifetime-deal cash appears only in 'one-time sales' and 'cash collected'. It is never added to MRR or ARR. A lifetime customer adds provider cost every month for as long as the product runs.

Sheet Assumptions
A1: ID | B1: Unsupported assumption (no Keplar data yet) | C1: Experiment that validates it (see docs/growth/EXPERIMENTS.md) | D1: Decision it affects
A2: E1 | B2: Qualified visits per month and their growth | C2: Publish the developer page + 2 search guides; read /admin/growth qualified visits weekly for 4 weeks | D2: Which scenario column is realistic
A3: E2 | B3: Demo-clip distribution produces qualified visits | C3: Post 4 real-run clips (founder accounts, no ads); count visits by utm | D3: Keep or stop channel 2
A4: E3 | B4: Visit to account created, account to activated | C4: First 100 activated users stage gate; funnel in /admin/growth | D4: Landing/onboarding fixes
A5: E4 | B5: Activated to paying conversion at current prices | C5: First 10 paying customers stage gate; ask research questions 8-10 | D5: Price/plan boundary proposals
A6: E5 | B6: Lite vs Plus plan mix | C6: Record plan on every payment | D6: Whether Plus ($44.99) is the right middle
A7: E6 | B7: Monthly churn by plan | C7: Cohort retention by plan after 60 days; cancellation reasons | D7: Retention work before acquisition
A8: E7 | B8: Tasks per month and other metered use per customer | C8: compute_ledger average per plan after 30 days of paid use | D8: Plan limits, heavy-user policy
A9: E8 | B9: Refund rate, dispute rate, international share | C9: Whop payments report after 20 payments | D9: Fee assumptions, refund policy
A10: E9 | B10: Free-model capacity covers Free demand | C10: Daily Free question count vs ~150 capacity; error rate 'limit' | D10: Free capacity fix / cheap fallback
A11: E10 | B11: Support minutes per customer | C11: Count emails and minutes for 30 days | D11: Support cost, tooling
A12: E11 | B12: Cost per visit of any paid channel | C12: Only after a budget, loss limit and authorization: capped test | D12: Whether paid acquisition is ever justified
